[2024-09-17 00:01:03,162][app.py:1891][ERROR][123145539010560] - Exception on /data-server [GET]
Traceback (most recent call last):
  File "/Users/layne/WorkSpace/sdn-project/.venv/lib/python3.9/site-packages/flask/app.py", line 2447, in wsgi_app
    response = self.full_dispatch_request()
  File "/Users/layne/WorkSpace/sdn-project/.venv/lib/python3.9/site-packages/flask/app.py", line 1952, in full_dispatch_request
    rv = self.handle_user_exception(e)
  File "/Users/layne/WorkSpace/sdn-project/.venv/lib/python3.9/site-packages/flask/app.py", line 1821, in handle_user_exception
    reraise(exc_type, exc_value, tb)
  File "/Users/layne/WorkSpace/sdn-project/.venv/lib/python3.9/site-packages/flask/_compat.py", line 39, in reraise
    raise value
  File "/Users/layne/WorkSpace/sdn-project/.venv/lib/python3.9/site-packages/flask/app.py", line 1950, in full_dispatch_request
    rv = self.dispatch_request()
  File "/Users/layne/WorkSpace/sdn-project/.venv/lib/python3.9/site-packages/flask/app.py", line 1936, in dispatch_request
    return self.view_functions[rule.endpoint](**req.view_args)
  File "/Users/layne/WorkSpace/sdn-project/simulate/topology.py", line 45, in data
    if gol.devices_stats[dictMsg['name']]==0:
AttributeError: module 'simulate.gol' has no attribute 'devices_stats'
[2024-09-17 00:01:50,856][app.py:1891][ERROR][123145522757632] - Exception on /rule-list [GET]
Traceback (most recent call last):
  File "/Users/layne/WorkSpace/sdn-project/.venv/lib/python3.9/site-packages/flask/app.py", line 2447, in wsgi_app
    response = self.full_dispatch_request()
  File "/Users/layne/WorkSpace/sdn-project/.venv/lib/python3.9/site-packages/flask/app.py", line 1952, in full_dispatch_request
    rv = self.handle_user_exception(e)
  File "/Users/layne/WorkSpace/sdn-project/.venv/lib/python3.9/site-packages/flask/app.py", line 1821, in handle_user_exception
    reraise(exc_type, exc_value, tb)
  File "/Users/layne/WorkSpace/sdn-project/.venv/lib/python3.9/site-packages/flask/_compat.py", line 39, in reraise
    raise value
  File "/Users/layne/WorkSpace/sdn-project/.venv/lib/python3.9/site-packages/flask/app.py", line 1950, in full_dispatch_request
    rv = self.dispatch_request()
  File "/Users/layne/WorkSpace/sdn-project/.venv/lib/python3.9/site-packages/flask/app.py", line 1936, in dispatch_request
    return self.view_functions[rule.endpoint](**req.view_args)
  File "/Users/layne/WorkSpace/sdn-project/simulate/rule.py", line 22, in rule_list
    url = remote_ip+"/stats/flow/"+gol.dpid
AttributeError: module 'simulate.gol' has no attribute 'dpid'
[2024-09-17 00:01:59,002][app.py:1891][ERROR][123145539547136] - Exception on /data-server [GET]
Traceback (most recent call last):
  File "/Users/layne/WorkSpace/sdn-project/.venv/lib/python3.9/site-packages/flask/app.py", line 2447, in wsgi_app
    response = self.full_dispatch_request()
  File "/Users/layne/WorkSpace/sdn-project/.venv/lib/python3.9/site-packages/flask/app.py", line 1952, in full_dispatch_request
    rv = self.handle_user_exception(e)
  File "/Users/layne/WorkSpace/sdn-project/.venv/lib/python3.9/site-packages/flask/app.py", line 1821, in handle_user_exception
    reraise(exc_type, exc_value, tb)
  File "/Users/layne/WorkSpace/sdn-project/.venv/lib/python3.9/site-packages/flask/_compat.py", line 39, in reraise
    raise value
  File "/Users/layne/WorkSpace/sdn-project/.venv/lib/python3.9/site-packages/flask/app.py", line 1950, in full_dispatch_request
    rv = self.dispatch_request()
  File "/Users/layne/WorkSpace/sdn-project/.venv/lib/python3.9/site-packages/flask/app.py", line 1936, in dispatch_request
    return self.view_functions[rule.endpoint](**req.view_args)
  File "/Users/layne/WorkSpace/sdn-project/simulate/topology.py", line 45, in data
    if gol.devices_stats[dictMsg['name']]==0:
AttributeError: module 'simulate.gol' has no attribute 'devices_stats'
[2024-09-17 00:02:12,452][app.py:1891][ERROR][123145539547136] - Exception on /data-server [GET]
Traceback (most recent call last):
  File "/Users/layne/WorkSpace/sdn-project/.venv/lib/python3.9/site-packages/flask/app.py", line 2447, in wsgi_app
    response = self.full_dispatch_request()
  File "/Users/layne/WorkSpace/sdn-project/.venv/lib/python3.9/site-packages/flask/app.py", line 1952, in full_dispatch_request
    rv = self.handle_user_exception(e)
  File "/Users/layne/WorkSpace/sdn-project/.venv/lib/python3.9/site-packages/flask/app.py", line 1821, in handle_user_exception
    reraise(exc_type, exc_value, tb)
  File "/Users/layne/WorkSpace/sdn-project/.venv/lib/python3.9/site-packages/flask/_compat.py", line 39, in reraise
    raise value
  File "/Users/layne/WorkSpace/sdn-project/.venv/lib/python3.9/site-packages/flask/app.py", line 1950, in full_dispatch_request
    rv = self.dispatch_request()
  File "/Users/layne/WorkSpace/sdn-project/.venv/lib/python3.9/site-packages/flask/app.py", line 1936, in dispatch_request
    return self.view_functions[rule.endpoint](**req.view_args)
  File "/Users/layne/WorkSpace/sdn-project/simulate/topology.py", line 45, in data
    if gol.devices_stats[dictMsg['name']]==0:
AttributeError: module 'simulate.gol' has no attribute 'devices_stats'
[2024-09-17 00:04:58,180][app.py:1891][ERROR][123145534238720] - Exception on /data-server [GET]
Traceback (most recent call last):
  File "/Users/layne/WorkSpace/sdn-project/.venv/lib/python3.9/site-packages/flask/app.py", line 2447, in wsgi_app
    response = self.full_dispatch_request()
  File "/Users/layne/WorkSpace/sdn-project/.venv/lib/python3.9/site-packages/flask/app.py", line 1952, in full_dispatch_request
    rv = self.handle_user_exception(e)
  File "/Users/layne/WorkSpace/sdn-project/.venv/lib/python3.9/site-packages/flask/app.py", line 1821, in handle_user_exception
    reraise(exc_type, exc_value, tb)
  File "/Users/layne/WorkSpace/sdn-project/.venv/lib/python3.9/site-packages/flask/_compat.py", line 39, in reraise
    raise value
  File "/Users/layne/WorkSpace/sdn-project/.venv/lib/python3.9/site-packages/flask/app.py", line 1950, in full_dispatch_request
    rv = self.dispatch_request()
  File "/Users/layne/WorkSpace/sdn-project/.venv/lib/python3.9/site-packages/flask/app.py", line 1936, in dispatch_request
    return self.view_functions[rule.endpoint](**req.view_args)
  File "/Users/layne/WorkSpace/sdn-project/simulate/topology.py", line 45, in data
    if gol.devices_stats[dictMsg['name']]==0:
AttributeError: module 'simulate.gol' has no attribute 'devices_stats'
[2024-09-17 00:06:00,963][app.py:1891][ERROR][123145605091328] - Exception on /data-server [GET]
Traceback (most recent call last):
  File "/Users/layne/WorkSpace/sdn-project/.venv/lib/python3.9/site-packages/flask/app.py", line 2447, in wsgi_app
    response = self.full_dispatch_request()
  File "/Users/layne/WorkSpace/sdn-project/.venv/lib/python3.9/site-packages/flask/app.py", line 1952, in full_dispatch_request
    rv = self.handle_user_exception(e)
  File "/Users/layne/WorkSpace/sdn-project/.venv/lib/python3.9/site-packages/flask/app.py", line 1821, in handle_user_exception
    reraise(exc_type, exc_value, tb)
  File "/Users/layne/WorkSpace/sdn-project/.venv/lib/python3.9/site-packages/flask/_compat.py", line 39, in reraise
    raise value
  File "/Users/layne/WorkSpace/sdn-project/.venv/lib/python3.9/site-packages/flask/app.py", line 1950, in full_dispatch_request
    rv = self.dispatch_request()
  File "/Users/layne/WorkSpace/sdn-project/.venv/lib/python3.9/site-packages/flask/app.py", line 1936, in dispatch_request
    return self.view_functions[rule.endpoint](**req.view_args)
  File "/Users/layne/WorkSpace/sdn-project/simulate/topology.py", line 45, in data
    if gol.devices_stats[dictMsg['name']]==0:
KeyError: 'vxlan'
[2024-09-17 00:06:08,017][app.py:1891][ERROR][123145622417408] - Exception on /data-server [GET]
Traceback (most recent call last):
  File "/Users/layne/WorkSpace/sdn-project/.venv/lib/python3.9/site-packages/flask/app.py", line 2447, in wsgi_app
    response = self.full_dispatch_request()
  File "/Users/layne/WorkSpace/sdn-project/.venv/lib/python3.9/site-packages/flask/app.py", line 1952, in full_dispatch_request
    rv = self.handle_user_exception(e)
  File "/Users/layne/WorkSpace/sdn-project/.venv/lib/python3.9/site-packages/flask/app.py", line 1821, in handle_user_exception
    reraise(exc_type, exc_value, tb)
  File "/Users/layne/WorkSpace/sdn-project/.venv/lib/python3.9/site-packages/flask/_compat.py", line 39, in reraise
    raise value
  File "/Users/layne/WorkSpace/sdn-project/.venv/lib/python3.9/site-packages/flask/app.py", line 1950, in full_dispatch_request
    rv = self.dispatch_request()
  File "/Users/layne/WorkSpace/sdn-project/.venv/lib/python3.9/site-packages/flask/app.py", line 1936, in dispatch_request
    return self.view_functions[rule.endpoint](**req.view_args)
  File "/Users/layne/WorkSpace/sdn-project/simulate/topology.py", line 45, in data
    if gol.devices_stats[dictMsg['name']]==0:
KeyError: 'vxlan'
[2024-09-17 10:20:41,340][app.py:1891][ERROR][123145506160640] - Exception on /rule-list [GET]
Traceback (most recent call last):
  File "/Users/layne/WorkSpace/sdn-project/.venv/lib/python3.9/site-packages/flask/app.py", line 2447, in wsgi_app
    response = self.full_dispatch_request()
  File "/Users/layne/WorkSpace/sdn-project/.venv/lib/python3.9/site-packages/flask/app.py", line 1952, in full_dispatch_request
    rv = self.handle_user_exception(e)
  File "/Users/layne/WorkSpace/sdn-project/.venv/lib/python3.9/site-packages/flask/app.py", line 1821, in handle_user_exception
    reraise(exc_type, exc_value, tb)
  File "/Users/layne/WorkSpace/sdn-project/.venv/lib/python3.9/site-packages/flask/_compat.py", line 39, in reraise
    raise value
  File "/Users/layne/WorkSpace/sdn-project/.venv/lib/python3.9/site-packages/flask/app.py", line 1950, in full_dispatch_request
    rv = self.dispatch_request()
  File "/Users/layne/WorkSpace/sdn-project/.venv/lib/python3.9/site-packages/flask/app.py", line 1936, in dispatch_request
    return self.view_functions[rule.endpoint](**req.view_args)
  File "/Users/layne/WorkSpace/sdn-project/simulate/rule.py", line 25, in rule_list
    data = json.loads(response.text)
  File "/Users/layne/WorkSpace/sdn-project/.venv/lib/python3.9/site-packages/flask/json/__init__.py", line 253, in loads
    return _json.loads(s, **kwargs)
  File "/Users/layne/WorkSpace/sdn-project/.venv/lib/python3.9/site-packages/simplejson/__init__.py", line 542, in loads
    return cls(encoding=encoding, **kw).decode(s)
  File "/Users/layne/WorkSpace/sdn-project/.venv/lib/python3.9/site-packages/simplejson/decoder.py", line 370, in decode
    obj, end = self.raw_decode(s)
  File "/Users/layne/WorkSpace/sdn-project/.venv/lib/python3.9/site-packages/simplejson/decoder.py", line 400, in raw_decode
    return self.scan_once(s, idx=_w(s, idx).end())
simplejson.errors.JSONDecodeError: Expecting value: line 1 column 1 (char 0)
[2024-09-17 10:22:41,336][app.py:1891][ERROR][123145649934336] - Exception on /rule-list [GET]
Traceback (most recent call last):
  File "/Users/layne/WorkSpace/sdn-project/.venv/lib/python3.9/site-packages/flask/app.py", line 2447, in wsgi_app
    response = self.full_dispatch_request()
  File "/Users/layne/WorkSpace/sdn-project/.venv/lib/python3.9/site-packages/flask/app.py", line 1952, in full_dispatch_request
    rv = self.handle_user_exception(e)
  File "/Users/layne/WorkSpace/sdn-project/.venv/lib/python3.9/site-packages/flask/app.py", line 1821, in handle_user_exception
    reraise(exc_type, exc_value, tb)
  File "/Users/layne/WorkSpace/sdn-project/.venv/lib/python3.9/site-packages/flask/_compat.py", line 39, in reraise
    raise value
  File "/Users/layne/WorkSpace/sdn-project/.venv/lib/python3.9/site-packages/flask/app.py", line 1950, in full_dispatch_request
    rv = self.dispatch_request()
  File "/Users/layne/WorkSpace/sdn-project/.venv/lib/python3.9/site-packages/flask/app.py", line 1936, in dispatch_request
    return self.view_functions[rule.endpoint](**req.view_args)
  File "/Users/layne/WorkSpace/sdn-project/simulate/rule.py", line 76, in rule_list
    sqlHelper.add(sql,args)
  File "/Users/layne/WorkSpace/sdn-project/simulate/utils/sqlhelper.py", line 25, in add
    rowcount = cursor.execute(sql,args)
  File "/Users/layne/WorkSpace/sdn-project/.venv/lib/python3.9/site-packages/pymysql/cursors.py", line 163, in execute
    result = self._query(query)
  File "/Users/layne/WorkSpace/sdn-project/.venv/lib/python3.9/site-packages/pymysql/cursors.py", line 321, in _query
    conn.query(q)
  File "/Users/layne/WorkSpace/sdn-project/.venv/lib/python3.9/site-packages/pymysql/connections.py", line 505, in query
    self._affected_rows = self._read_query_result(unbuffered=unbuffered)
  File "/Users/layne/WorkSpace/sdn-project/.venv/lib/python3.9/site-packages/pymysql/connections.py", line 724, in _read_query_result
    result.read()
  File "/Users/layne/WorkSpace/sdn-project/.venv/lib/python3.9/site-packages/pymysql/connections.py", line 1069, in read
    first_packet = self.connection._read_packet()
  File "/Users/layne/WorkSpace/sdn-project/.venv/lib/python3.9/site-packages/pymysql/connections.py", line 676, in _read_packet
    packet.raise_for_error()
  File "/Users/layne/WorkSpace/sdn-project/.venv/lib/python3.9/site-packages/pymysql/protocol.py", line 223, in raise_for_error
    err.raise_mysql_exception(self._data)
  File "/Users/layne/WorkSpace/sdn-project/.venv/lib/python3.9/site-packages/pymysql/err.py", line 107, in raise_mysql_exception
    raise errorclass(errno, errval)
pymysql.err.ProgrammingError: (1146, "Table 'mydata.rules' doesn't exist")
[2024-09-17 10:22:49,985][app.py:1891][ERROR][123145666723840] - Exception on /rule-list [GET]
Traceback (most recent call last):
  File "/Users/layne/WorkSpace/sdn-project/.venv/lib/python3.9/site-packages/flask/app.py", line 2447, in wsgi_app
    response = self.full_dispatch_request()
  File "/Users/layne/WorkSpace/sdn-project/.venv/lib/python3.9/site-packages/flask/app.py", line 1952, in full_dispatch_request
    rv = self.handle_user_exception(e)
  File "/Users/layne/WorkSpace/sdn-project/.venv/lib/python3.9/site-packages/flask/app.py", line 1821, in handle_user_exception
    reraise(exc_type, exc_value, tb)
  File "/Users/layne/WorkSpace/sdn-project/.venv/lib/python3.9/site-packages/flask/_compat.py", line 39, in reraise
    raise value
  File "/Users/layne/WorkSpace/sdn-project/.venv/lib/python3.9/site-packages/flask/app.py", line 1950, in full_dispatch_request
    rv = self.dispatch_request()
  File "/Users/layne/WorkSpace/sdn-project/.venv/lib/python3.9/site-packages/flask/app.py", line 1936, in dispatch_request
    return self.view_functions[rule.endpoint](**req.view_args)
  File "/Users/layne/WorkSpace/sdn-project/simulate/rule.py", line 76, in rule_list
    sqlHelper.add(sql,args)
  File "/Users/layne/WorkSpace/sdn-project/simulate/utils/sqlhelper.py", line 25, in add
    rowcount = cursor.execute(sql,args)
  File "/Users/layne/WorkSpace/sdn-project/.venv/lib/python3.9/site-packages/pymysql/cursors.py", line 163, in execute
    result = self._query(query)
  File "/Users/layne/WorkSpace/sdn-project/.venv/lib/python3.9/site-packages/pymysql/cursors.py", line 321, in _query
    conn.query(q)
  File "/Users/layne/WorkSpace/sdn-project/.venv/lib/python3.9/site-packages/pymysql/connections.py", line 505, in query
    self._affected_rows = self._read_query_result(unbuffered=unbuffered)
  File "/Users/layne/WorkSpace/sdn-project/.venv/lib/python3.9/site-packages/pymysql/connections.py", line 724, in _read_query_result
    result.read()
  File "/Users/layne/WorkSpace/sdn-project/.venv/lib/python3.9/site-packages/pymysql/connections.py", line 1069, in read
    first_packet = self.connection._read_packet()
  File "/Users/layne/WorkSpace/sdn-project/.venv/lib/python3.9/site-packages/pymysql/connections.py", line 676, in _read_packet
    packet.raise_for_error()
  File "/Users/layne/WorkSpace/sdn-project/.venv/lib/python3.9/site-packages/pymysql/protocol.py", line 223, in raise_for_error
    err.raise_mysql_exception(self._data)
  File "/Users/layne/WorkSpace/sdn-project/.venv/lib/python3.9/site-packages/pymysql/err.py", line 107, in raise_mysql_exception
    raise errorclass(errno, errval)
pymysql.err.ProgrammingError: (1146, "Table 'mydata.rules' doesn't exist")
[2024-09-17 11:04:05,991][app.py:1891][ERROR][123145717628928] - Exception on /portvalue [GET]
Traceback (most recent call last):
  File "/Users/layne/WorkSpace/sdn-project/.venv/lib/python3.9/site-packages/flask/app.py", line 2447, in wsgi_app
    response = self.full_dispatch_request()
  File "/Users/layne/WorkSpace/sdn-project/.venv/lib/python3.9/site-packages/flask/app.py", line 1952, in full_dispatch_request
    rv = self.handle_user_exception(e)
  File "/Users/layne/WorkSpace/sdn-project/.venv/lib/python3.9/site-packages/flask/app.py", line 1821, in handle_user_exception
    reraise(exc_type, exc_value, tb)
  File "/Users/layne/WorkSpace/sdn-project/.venv/lib/python3.9/site-packages/flask/_compat.py", line 39, in reraise
    raise value
  File "/Users/layne/WorkSpace/sdn-project/.venv/lib/python3.9/site-packages/flask/app.py", line 1950, in full_dispatch_request
    rv = self.dispatch_request()
  File "/Users/layne/WorkSpace/sdn-project/.venv/lib/python3.9/site-packages/flask/app.py", line 1936, in dispatch_request
    return self.view_functions[rule.endpoint](**req.view_args)
  File "/Users/layne/WorkSpace/sdn-project/simulate/nodes.py", line 68, in get_stats_port
    gol.host_port.append(dict['port_no'])
AttributeError: module 'simulate.gol' has no attribute 'host_port'
[2024-09-17 11:09:08,658][app.py:1891][ERROR][123145626337280] - Exception on /rule-list [GET]
Traceback (most recent call last):
  File "/Users/layne/WorkSpace/sdn-project/.venv/lib/python3.9/site-packages/flask/app.py", line 2447, in wsgi_app
    response = self.full_dispatch_request()
  File "/Users/layne/WorkSpace/sdn-project/.venv/lib/python3.9/site-packages/flask/app.py", line 1952, in full_dispatch_request
    rv = self.handle_user_exception(e)
  File "/Users/layne/WorkSpace/sdn-project/.venv/lib/python3.9/site-packages/flask/app.py", line 1821, in handle_user_exception
    reraise(exc_type, exc_value, tb)
  File "/Users/layne/WorkSpace/sdn-project/.venv/lib/python3.9/site-packages/flask/_compat.py", line 39, in reraise
    raise value
  File "/Users/layne/WorkSpace/sdn-project/.venv/lib/python3.9/site-packages/flask/app.py", line 1950, in full_dispatch_request
    rv = self.dispatch_request()
  File "/Users/layne/WorkSpace/sdn-project/.venv/lib/python3.9/site-packages/flask/app.py", line 1936, in dispatch_request
    return self.view_functions[rule.endpoint](**req.view_args)
  File "/Users/layne/WorkSpace/sdn-project/simulate/rule.py", line 47, in rule_list
    flow_entry_dict_item['match_in_port'] = item['match']['in_port']
KeyError: 'in_port'
[2024-09-17 11:11:22,923][app.py:1891][ERROR][123145643126784] - Exception on /rule-list [GET]
Traceback (most recent call last):
  File "/Users/layne/WorkSpace/sdn-project/.venv/lib/python3.9/site-packages/flask/app.py", line 2447, in wsgi_app
    response = self.full_dispatch_request()
  File "/Users/layne/WorkSpace/sdn-project/.venv/lib/python3.9/site-packages/flask/app.py", line 1952, in full_dispatch_request
    rv = self.handle_user_exception(e)
  File "/Users/layne/WorkSpace/sdn-project/.venv/lib/python3.9/site-packages/flask/app.py", line 1821, in handle_user_exception
    reraise(exc_type, exc_value, tb)
  File "/Users/layne/WorkSpace/sdn-project/.venv/lib/python3.9/site-packages/flask/_compat.py", line 39, in reraise
    raise value
  File "/Users/layne/WorkSpace/sdn-project/.venv/lib/python3.9/site-packages/flask/app.py", line 1950, in full_dispatch_request
    rv = self.dispatch_request()
  File "/Users/layne/WorkSpace/sdn-project/.venv/lib/python3.9/site-packages/flask/app.py", line 1936, in dispatch_request
    return self.view_functions[rule.endpoint](**req.view_args)
  File "/Users/layne/WorkSpace/sdn-project/simulate/rule.py", line 47, in rule_list
    flow_entry_dict_item['match_in_port'] = item['match']['in_port']
KeyError: 'in_port'
[2024-09-17 11:11:26,966][app.py:1891][ERROR][123145643126784] - Exception on /rule-list [GET]
Traceback (most recent call last):
  File "/Users/layne/WorkSpace/sdn-project/.venv/lib/python3.9/site-packages/flask/app.py", line 2447, in wsgi_app
    response = self.full_dispatch_request()
  File "/Users/layne/WorkSpace/sdn-project/.venv/lib/python3.9/site-packages/flask/app.py", line 1952, in full_dispatch_request
    rv = self.handle_user_exception(e)
  File "/Users/layne/WorkSpace/sdn-project/.venv/lib/python3.9/site-packages/flask/app.py", line 1821, in handle_user_exception
    reraise(exc_type, exc_value, tb)
  File "/Users/layne/WorkSpace/sdn-project/.venv/lib/python3.9/site-packages/flask/_compat.py", line 39, in reraise
    raise value
  File "/Users/layne/WorkSpace/sdn-project/.venv/lib/python3.9/site-packages/flask/app.py", line 1950, in full_dispatch_request
    rv = self.dispatch_request()
  File "/Users/layne/WorkSpace/sdn-project/.venv/lib/python3.9/site-packages/flask/app.py", line 1936, in dispatch_request
    return self.view_functions[rule.endpoint](**req.view_args)
  File "/Users/layne/WorkSpace/sdn-project/simulate/rule.py", line 47, in rule_list
    flow_entry_dict_item['match_in_port'] = item['match']['in_port']
KeyError: 'in_port'
[2024-09-17 11:11:28,973][app.py:1891][ERROR][123145626337280] - Exception on /rule-list [GET]
Traceback (most recent call last):
  File "/Users/layne/WorkSpace/sdn-project/.venv/lib/python3.9/site-packages/flask/app.py", line 2447, in wsgi_app
    response = self.full_dispatch_request()
  File "/Users/layne/WorkSpace/sdn-project/.venv/lib/python3.9/site-packages/flask/app.py", line 1952, in full_dispatch_request
    rv = self.handle_user_exception(e)
  File "/Users/layne/WorkSpace/sdn-project/.venv/lib/python3.9/site-packages/flask/app.py", line 1821, in handle_user_exception
    reraise(exc_type, exc_value, tb)
  File "/Users/layne/WorkSpace/sdn-project/.venv/lib/python3.9/site-packages/flask/_compat.py", line 39, in reraise
    raise value
  File "/Users/layne/WorkSpace/sdn-project/.venv/lib/python3.9/site-packages/flask/app.py", line 1950, in full_dispatch_request
    rv = self.dispatch_request()
  File "/Users/layne/WorkSpace/sdn-project/.venv/lib/python3.9/site-packages/flask/app.py", line 1936, in dispatch_request
    return self.view_functions[rule.endpoint](**req.view_args)
  File "/Users/layne/WorkSpace/sdn-project/simulate/rule.py", line 47, in rule_list
    flow_entry_dict_item['match_in_port'] = item['match']['in_port']
KeyError: 'in_port'
[2024-09-17 11:13:00,423][app.py:1891][ERROR][123145626337280] - Exception on /rule-list [GET]
Traceback (most recent call last):
  File "/Users/layne/WorkSpace/sdn-project/.venv/lib/python3.9/site-packages/flask/app.py", line 2447, in wsgi_app
    response = self.full_dispatch_request()
  File "/Users/layne/WorkSpace/sdn-project/.venv/lib/python3.9/site-packages/flask/app.py", line 1952, in full_dispatch_request
    rv = self.handle_user_exception(e)
  File "/Users/layne/WorkSpace/sdn-project/.venv/lib/python3.9/site-packages/flask/app.py", line 1821, in handle_user_exception
    reraise(exc_type, exc_value, tb)
  File "/Users/layne/WorkSpace/sdn-project/.venv/lib/python3.9/site-packages/flask/_compat.py", line 39, in reraise
    raise value
  File "/Users/layne/WorkSpace/sdn-project/.venv/lib/python3.9/site-packages/flask/app.py", line 1950, in full_dispatch_request
    rv = self.dispatch_request()
  File "/Users/layne/WorkSpace/sdn-project/.venv/lib/python3.9/site-packages/flask/app.py", line 1936, in dispatch_request
    return self.view_functions[rule.endpoint](**req.view_args)
  File "/Users/layne/WorkSpace/sdn-project/simulate/rule.py", line 47, in rule_list
    flow_entry_dict_item['match_in_port'] = item['match']['in_port']
KeyError: 'in_port'
[2024-09-17 11:13:16,989][app.py:1891][ERROR][123145643126784] - Exception on /rule-list [GET]
Traceback (most recent call last):
  File "/Users/layne/WorkSpace/sdn-project/.venv/lib/python3.9/site-packages/flask/app.py", line 2447, in wsgi_app
    response = self.full_dispatch_request()
  File "/Users/layne/WorkSpace/sdn-project/.venv/lib/python3.9/site-packages/flask/app.py", line 1952, in full_dispatch_request
    rv = self.handle_user_exception(e)
  File "/Users/layne/WorkSpace/sdn-project/.venv/lib/python3.9/site-packages/flask/app.py", line 1821, in handle_user_exception
    reraise(exc_type, exc_value, tb)
  File "/Users/layne/WorkSpace/sdn-project/.venv/lib/python3.9/site-packages/flask/_compat.py", line 39, in reraise
    raise value
  File "/Users/layne/WorkSpace/sdn-project/.venv/lib/python3.9/site-packages/flask/app.py", line 1950, in full_dispatch_request
    rv = self.dispatch_request()
  File "/Users/layne/WorkSpace/sdn-project/.venv/lib/python3.9/site-packages/flask/app.py", line 1936, in dispatch_request
    return self.view_functions[rule.endpoint](**req.view_args)
  File "/Users/layne/WorkSpace/sdn-project/simulate/rule.py", line 47, in rule_list
    flow_entry_dict_item['match_in_port'] = item['match']['in_port']
KeyError: 'in_port'
[2024-09-17 11:14:36,565][app.py:1891][ERROR][123145626337280] - Exception on /rule-list [GET]
Traceback (most recent call last):
  File "/Users/layne/WorkSpace/sdn-project/.venv/lib/python3.9/site-packages/flask/app.py", line 2447, in wsgi_app
    response = self.full_dispatch_request()
  File "/Users/layne/WorkSpace/sdn-project/.venv/lib/python3.9/site-packages/flask/app.py", line 1952, in full_dispatch_request
    rv = self.handle_user_exception(e)
  File "/Users/layne/WorkSpace/sdn-project/.venv/lib/python3.9/site-packages/flask/app.py", line 1821, in handle_user_exception
    reraise(exc_type, exc_value, tb)
  File "/Users/layne/WorkSpace/sdn-project/.venv/lib/python3.9/site-packages/flask/_compat.py", line 39, in reraise
    raise value
  File "/Users/layne/WorkSpace/sdn-project/.venv/lib/python3.9/site-packages/flask/app.py", line 1950, in full_dispatch_request
    rv = self.dispatch_request()
  File "/Users/layne/WorkSpace/sdn-project/.venv/lib/python3.9/site-packages/flask/app.py", line 1936, in dispatch_request
    return self.view_functions[rule.endpoint](**req.view_args)
  File "/Users/layne/WorkSpace/sdn-project/simulate/rule.py", line 47, in rule_list
    flow_entry_dict_item['match_in_port'] = item['match']['in_port']
KeyError: 'in_port'
[2024-09-17 11:14:36,589][app.py:1891][ERROR][123145677242368] - Exception on /rule-list [GET]
Traceback (most recent call last):
  File "/Users/layne/WorkSpace/sdn-project/.venv/lib/python3.9/site-packages/flask/app.py", line 2447, in wsgi_app
    response = self.full_dispatch_request()
  File "/Users/layne/WorkSpace/sdn-project/.venv/lib/python3.9/site-packages/flask/app.py", line 1952, in full_dispatch_request
    rv = self.handle_user_exception(e)
  File "/Users/layne/WorkSpace/sdn-project/.venv/lib/python3.9/site-packages/flask/app.py", line 1821, in handle_user_exception
    reraise(exc_type, exc_value, tb)
  File "/Users/layne/WorkSpace/sdn-project/.venv/lib/python3.9/site-packages/flask/_compat.py", line 39, in reraise
    raise value
  File "/Users/layne/WorkSpace/sdn-project/.venv/lib/python3.9/site-packages/flask/app.py", line 1950, in full_dispatch_request
    rv = self.dispatch_request()
  File "/Users/layne/WorkSpace/sdn-project/.venv/lib/python3.9/site-packages/flask/app.py", line 1936, in dispatch_request
    return self.view_functions[rule.endpoint](**req.view_args)
  File "/Users/layne/WorkSpace/sdn-project/simulate/rule.py", line 47, in rule_list
    flow_entry_dict_item['match_in_port'] = item['match']['in_port']
KeyError: 'in_port'
[2024-09-17 11:15:20,590][app.py:1891][ERROR][123145643126784] - Exception on /rule-list [GET]
Traceback (most recent call last):
  File "/Users/layne/WorkSpace/sdn-project/.venv/lib/python3.9/site-packages/flask/app.py", line 2447, in wsgi_app
    response = self.full_dispatch_request()
  File "/Users/layne/WorkSpace/sdn-project/.venv/lib/python3.9/site-packages/flask/app.py", line 1952, in full_dispatch_request
    rv = self.handle_user_exception(e)
  File "/Users/layne/WorkSpace/sdn-project/.venv/lib/python3.9/site-packages/flask/app.py", line 1821, in handle_user_exception
    reraise(exc_type, exc_value, tb)
  File "/Users/layne/WorkSpace/sdn-project/.venv/lib/python3.9/site-packages/flask/_compat.py", line 39, in reraise
    raise value
  File "/Users/layne/WorkSpace/sdn-project/.venv/lib/python3.9/site-packages/flask/app.py", line 1950, in full_dispatch_request
    rv = self.dispatch_request()
  File "/Users/layne/WorkSpace/sdn-project/.venv/lib/python3.9/site-packages/flask/app.py", line 1936, in dispatch_request
    return self.view_functions[rule.endpoint](**req.view_args)
  File "/Users/layne/WorkSpace/sdn-project/simulate/rule.py", line 47, in rule_list
    flow_entry_dict_item['match_in_port'] = item['match']['in_port']
KeyError: 'in_port'
[2024-09-17 11:20:18,937][app.py:1891][ERROR][123145533636608] - Exception on /rule-list [GET]
Traceback (most recent call last):
  File "/Users/layne/WorkSpace/sdn-project/.venv/lib/python3.9/site-packages/flask/app.py", line 2447, in wsgi_app
    response = self.full_dispatch_request()
  File "/Users/layne/WorkSpace/sdn-project/.venv/lib/python3.9/site-packages/flask/app.py", line 1952, in full_dispatch_request
    rv = self.handle_user_exception(e)
  File "/Users/layne/WorkSpace/sdn-project/.venv/lib/python3.9/site-packages/flask/app.py", line 1821, in handle_user_exception
    reraise(exc_type, exc_value, tb)
  File "/Users/layne/WorkSpace/sdn-project/.venv/lib/python3.9/site-packages/flask/_compat.py", line 39, in reraise
    raise value
  File "/Users/layne/WorkSpace/sdn-project/.venv/lib/python3.9/site-packages/flask/app.py", line 1950, in full_dispatch_request
    rv = self.dispatch_request()
  File "/Users/layne/WorkSpace/sdn-project/.venv/lib/python3.9/site-packages/flask/app.py", line 1936, in dispatch_request
    return self.view_functions[rule.endpoint](**req.view_args)
  File "/Users/layne/WorkSpace/sdn-project/simulate/rule.py", line 47, in rule_list
    if not item['match']['in_port']:
KeyError: 'in_port'
[2024-09-17 11:20:26,096][app.py:1891][ERROR][123145550426112] - Exception on /rule-list [GET]
Traceback (most recent call last):
  File "/Users/layne/WorkSpace/sdn-project/.venv/lib/python3.9/site-packages/flask/app.py", line 2447, in wsgi_app
    response = self.full_dispatch_request()
  File "/Users/layne/WorkSpace/sdn-project/.venv/lib/python3.9/site-packages/flask/app.py", line 1952, in full_dispatch_request
    rv = self.handle_user_exception(e)
  File "/Users/layne/WorkSpace/sdn-project/.venv/lib/python3.9/site-packages/flask/app.py", line 1821, in handle_user_exception
    reraise(exc_type, exc_value, tb)
  File "/Users/layne/WorkSpace/sdn-project/.venv/lib/python3.9/site-packages/flask/_compat.py", line 39, in reraise
    raise value
  File "/Users/layne/WorkSpace/sdn-project/.venv/lib/python3.9/site-packages/flask/app.py", line 1950, in full_dispatch_request
    rv = self.dispatch_request()
  File "/Users/layne/WorkSpace/sdn-project/.venv/lib/python3.9/site-packages/flask/app.py", line 1936, in dispatch_request
    return self.view_functions[rule.endpoint](**req.view_args)
  File "/Users/layne/WorkSpace/sdn-project/simulate/rule.py", line 47, in rule_list
    if not item['match']['in_port']:
KeyError: 'in_port'
[2024-09-17 11:21:13,782][app.py:1891][ERROR][123145533636608] - Exception on /rule-list [GET]
Traceback (most recent call last):
  File "/Users/layne/WorkSpace/sdn-project/.venv/lib/python3.9/site-packages/flask/app.py", line 2447, in wsgi_app
    response = self.full_dispatch_request()
  File "/Users/layne/WorkSpace/sdn-project/.venv/lib/python3.9/site-packages/flask/app.py", line 1952, in full_dispatch_request
    rv = self.handle_user_exception(e)
  File "/Users/layne/WorkSpace/sdn-project/.venv/lib/python3.9/site-packages/flask/app.py", line 1821, in handle_user_exception
    reraise(exc_type, exc_value, tb)
  File "/Users/layne/WorkSpace/sdn-project/.venv/lib/python3.9/site-packages/flask/_compat.py", line 39, in reraise
    raise value
  File "/Users/layne/WorkSpace/sdn-project/.venv/lib/python3.9/site-packages/flask/app.py", line 1950, in full_dispatch_request
    rv = self.dispatch_request()
  File "/Users/layne/WorkSpace/sdn-project/.venv/lib/python3.9/site-packages/flask/app.py", line 1936, in dispatch_request
    return self.view_functions[rule.endpoint](**req.view_args)
  File "/Users/layne/WorkSpace/sdn-project/simulate/rule.py", line 47, in rule_list
    if not item['match']['in_port']:
KeyError: 'in_port'
[2024-09-17 11:21:24,801][app.py:1891][ERROR][123145605492736] - Exception on /rule-list [GET]
Traceback (most recent call last):
  File "/Users/layne/WorkSpace/sdn-project/.venv/lib/python3.9/site-packages/flask/app.py", line 2447, in wsgi_app
    response = self.full_dispatch_request()
  File "/Users/layne/WorkSpace/sdn-project/.venv/lib/python3.9/site-packages/flask/app.py", line 1952, in full_dispatch_request
    rv = self.handle_user_exception(e)
  File "/Users/layne/WorkSpace/sdn-project/.venv/lib/python3.9/site-packages/flask/app.py", line 1821, in handle_user_exception
    reraise(exc_type, exc_value, tb)
  File "/Users/layne/WorkSpace/sdn-project/.venv/lib/python3.9/site-packages/flask/_compat.py", line 39, in reraise
    raise value
  File "/Users/layne/WorkSpace/sdn-project/.venv/lib/python3.9/site-packages/flask/app.py", line 1950, in full_dispatch_request
    rv = self.dispatch_request()
  File "/Users/layne/WorkSpace/sdn-project/.venv/lib/python3.9/site-packages/flask/app.py", line 1936, in dispatch_request
    return self.view_functions[rule.endpoint](**req.view_args)
  File "/Users/layne/WorkSpace/sdn-project/simulate/rule.py", line 48, in rule_list
    flow_entry_dict_item['match_in_port'] = item['match']['in_port']
KeyError: 'in_port'
[2024-09-17 11:27:44,729][app.py:1891][ERROR][123145596391424] - Exception on /portvalue [GET]
Traceback (most recent call last):
  File "/Users/layne/WorkSpace/sdn-project/.venv/lib/python3.9/site-packages/flask/app.py", line 2447, in wsgi_app
    response = self.full_dispatch_request()
  File "/Users/layne/WorkSpace/sdn-project/.venv/lib/python3.9/site-packages/flask/app.py", line 1952, in full_dispatch_request
    rv = self.handle_user_exception(e)
  File "/Users/layne/WorkSpace/sdn-project/.venv/lib/python3.9/site-packages/flask/app.py", line 1821, in handle_user_exception
    reraise(exc_type, exc_value, tb)
  File "/Users/layne/WorkSpace/sdn-project/.venv/lib/python3.9/site-packages/flask/_compat.py", line 39, in reraise
    raise value
  File "/Users/layne/WorkSpace/sdn-project/.venv/lib/python3.9/site-packages/flask/app.py", line 1950, in full_dispatch_request
    rv = self.dispatch_request()
  File "/Users/layne/WorkSpace/sdn-project/.venv/lib/python3.9/site-packages/flask/app.py", line 1936, in dispatch_request
    return self.view_functions[rule.endpoint](**req.view_args)
  File "/Users/layne/WorkSpace/sdn-project/simulate/nodes.py", line 68, in get_stats_port
    gol.host_port.append(dict['port_no'])
AttributeError: module 'simulate.gol' has no attribute 'host_port'
[2024-09-17 11:28:27,863][app.py:1891][ERROR][123145596391424] - Exception on /portvalue [GET]
Traceback (most recent call last):
  File "/Users/layne/WorkSpace/sdn-project/.venv/lib/python3.9/site-packages/flask/app.py", line 2447, in wsgi_app
    response = self.full_dispatch_request()
  File "/Users/layne/WorkSpace/sdn-project/.venv/lib/python3.9/site-packages/flask/app.py", line 1952, in full_dispatch_request
    rv = self.handle_user_exception(e)
  File "/Users/layne/WorkSpace/sdn-project/.venv/lib/python3.9/site-packages/flask/app.py", line 1821, in handle_user_exception
    reraise(exc_type, exc_value, tb)
  File "/Users/layne/WorkSpace/sdn-project/.venv/lib/python3.9/site-packages/flask/_compat.py", line 39, in reraise
    raise value
  File "/Users/layne/WorkSpace/sdn-project/.venv/lib/python3.9/site-packages/flask/app.py", line 1950, in full_dispatch_request
    rv = self.dispatch_request()
  File "/Users/layne/WorkSpace/sdn-project/.venv/lib/python3.9/site-packages/flask/app.py", line 1936, in dispatch_request
    return self.view_functions[rule.endpoint](**req.view_args)
  File "/Users/layne/WorkSpace/sdn-project/simulate/nodes.py", line 68, in get_stats_port
    gol.host_port.append(dict['port_no'])
AttributeError: module 'simulate.gol' has no attribute 'host_port'
[2024-09-17 11:51:59,935][app.py:1891][ERROR][123145498009600] - Exception on /portvalue [GET]
Traceback (most recent call last):
  File "/Users/layne/WorkSpace/sdn-project/.venv/lib/python3.9/site-packages/flask/app.py", line 2447, in wsgi_app
    response = self.full_dispatch_request()
  File "/Users/layne/WorkSpace/sdn-project/.venv/lib/python3.9/site-packages/flask/app.py", line 1952, in full_dispatch_request
    rv = self.handle_user_exception(e)
  File "/Users/layne/WorkSpace/sdn-project/.venv/lib/python3.9/site-packages/flask/app.py", line 1821, in handle_user_exception
    reraise(exc_type, exc_value, tb)
  File "/Users/layne/WorkSpace/sdn-project/.venv/lib/python3.9/site-packages/flask/_compat.py", line 39, in reraise
    raise value
  File "/Users/layne/WorkSpace/sdn-project/.venv/lib/python3.9/site-packages/flask/app.py", line 1950, in full_dispatch_request
    rv = self.dispatch_request()
  File "/Users/layne/WorkSpace/sdn-project/.venv/lib/python3.9/site-packages/flask/app.py", line 1936, in dispatch_request
    return self.view_functions[rule.endpoint](**req.view_args)
  File "/Users/layne/WorkSpace/sdn-project/simulate/nodes.py", line 68, in get_stats_port
    gol.host_port.append(dict['port_no'])
AttributeError: module 'simulate.gol' has no attribute 'host_port'
[2024-09-17 11:55:31,354][app.py:1891][ERROR][123145415933952] - Exception on /portvalue [GET]
Traceback (most recent call last):
  File "/Users/layne/WorkSpace/sdn-project/.venv/lib/python3.9/site-packages/flask/app.py", line 2447, in wsgi_app
    response = self.full_dispatch_request()
  File "/Users/layne/WorkSpace/sdn-project/.venv/lib/python3.9/site-packages/flask/app.py", line 1952, in full_dispatch_request
    rv = self.handle_user_exception(e)
  File "/Users/layne/WorkSpace/sdn-project/.venv/lib/python3.9/site-packages/flask/app.py", line 1821, in handle_user_exception
    reraise(exc_type, exc_value, tb)
  File "/Users/layne/WorkSpace/sdn-project/.venv/lib/python3.9/site-packages/flask/_compat.py", line 39, in reraise
    raise value
  File "/Users/layne/WorkSpace/sdn-project/.venv/lib/python3.9/site-packages/flask/app.py", line 1950, in full_dispatch_request
    rv = self.dispatch_request()
  File "/Users/layne/WorkSpace/sdn-project/.venv/lib/python3.9/site-packages/flask/app.py", line 1936, in dispatch_request
    return self.view_functions[rule.endpoint](**req.view_args)
  File "/Users/layne/WorkSpace/sdn-project/simulate/nodes.py", line 66, in get_stats_port
    gol.host_port.append(dict['port_no'])
AttributeError: module 'simulate.gol' has no attribute 'host_port'
[2024-09-17 11:56:21,073][app.py:1891][ERROR][123145433260032] - Exception on /portvalue [GET]
Traceback (most recent call last):
  File "/Users/layne/WorkSpace/sdn-project/.venv/lib/python3.9/site-packages/flask/app.py", line 2447, in wsgi_app
    response = self.full_dispatch_request()
  File "/Users/layne/WorkSpace/sdn-project/.venv/lib/python3.9/site-packages/flask/app.py", line 1952, in full_dispatch_request
    rv = self.handle_user_exception(e)
  File "/Users/layne/WorkSpace/sdn-project/.venv/lib/python3.9/site-packages/flask/app.py", line 1821, in handle_user_exception
    reraise(exc_type, exc_value, tb)
  File "/Users/layne/WorkSpace/sdn-project/.venv/lib/python3.9/site-packages/flask/_compat.py", line 39, in reraise
    raise value
  File "/Users/layne/WorkSpace/sdn-project/.venv/lib/python3.9/site-packages/flask/app.py", line 1950, in full_dispatch_request
    rv = self.dispatch_request()
  File "/Users/layne/WorkSpace/sdn-project/.venv/lib/python3.9/site-packages/flask/app.py", line 1936, in dispatch_request
    return self.view_functions[rule.endpoint](**req.view_args)
  File "/Users/layne/WorkSpace/sdn-project/simulate/nodes.py", line 66, in get_stats_port
    gol.host_port.append(dict['port_no'])
AttributeError: module 'simulate.gol' has no attribute 'host_port'
[2024-09-17 11:59:21,561][app.py:1891][ERROR][123145519550464] - Exception on /portvalue [GET]
Traceback (most recent call last):
  File "/Users/layne/WorkSpace/sdn-project/.venv/lib/python3.9/site-packages/flask/app.py", line 2447, in wsgi_app
    response = self.full_dispatch_request()
  File "/Users/layne/WorkSpace/sdn-project/.venv/lib/python3.9/site-packages/flask/app.py", line 1952, in full_dispatch_request
    rv = self.handle_user_exception(e)
  File "/Users/layne/WorkSpace/sdn-project/.venv/lib/python3.9/site-packages/flask/app.py", line 1821, in handle_user_exception
    reraise(exc_type, exc_value, tb)
  File "/Users/layne/WorkSpace/sdn-project/.venv/lib/python3.9/site-packages/flask/_compat.py", line 39, in reraise
    raise value
  File "/Users/layne/WorkSpace/sdn-project/.venv/lib/python3.9/site-packages/flask/app.py", line 1950, in full_dispatch_request
    rv = self.dispatch_request()
  File "/Users/layne/WorkSpace/sdn-project/.venv/lib/python3.9/site-packages/flask/app.py", line 1936, in dispatch_request
    return self.view_functions[rule.endpoint](**req.view_args)
  File "/Users/layne/WorkSpace/sdn-project/simulate/nodes.py", line 66, in get_stats_port
    gol.host_port.append(dict['port_no'])
AttributeError: module 'simulate.gol' has no attribute 'host_port'
