[2024-09-13 00:19:02,917][app.py:1891][ERROR][4580859968] - Exception on /data-server [GET]
Traceback (most recent call last):
  File "/Users/layne/WorkSpace/sdn-project/.venv/lib/python3.9/site-packages/flask/app.py", line 2447, in wsgi_app
    response = self.full_dispatch_request()
  File "/Users/layne/WorkSpace/sdn-project/.venv/lib/python3.9/site-packages/flask/app.py", line 1952, in full_dispatch_request
    rv = self.handle_user_exception(e)
  File "/Users/layne/WorkSpace/sdn-project/.venv/lib/python3.9/site-packages/flask/app.py", line 1821, in handle_user_exception
    reraise(exc_type, exc_value, tb)
  File "/Users/layne/WorkSpace/sdn-project/.venv/lib/python3.9/site-packages/flask/_compat.py", line 39, in reraise
    raise value
  File "/Users/layne/WorkSpace/sdn-project/.venv/lib/python3.9/site-packages/flask/app.py", line 1950, in full_dispatch_request
    rv = self.dispatch_request()
  File "/Users/layne/WorkSpace/sdn-project/.venv/lib/python3.9/site-packages/flask/app.py", line 1936, in dispatch_request
    return self.view_functions[rule.endpoint](**req.view_args)
  File "/Users/layne/WorkSpace/sdn-project/simulate/topology.py", line 27, in data
    req=requests.get(remote_ip+"/stats/portdesc/"+gol.dpid, timeout=(3,20))
AttributeError: module 'simulate.gol' has no attribute 'dpid'
[2024-09-13 00:23:19,392][app.py:1891][ERROR][4516133440] - Exception on /data-server [GET]
Traceback (most recent call last):
  File "/Users/layne/WorkSpace/sdn-project/.venv/lib/python3.9/site-packages/flask/app.py", line 2447, in wsgi_app
    response = self.full_dispatch_request()
  File "/Users/layne/WorkSpace/sdn-project/.venv/lib/python3.9/site-packages/flask/app.py", line 1952, in full_dispatch_request
    rv = self.handle_user_exception(e)
  File "/Users/layne/WorkSpace/sdn-project/.venv/lib/python3.9/site-packages/flask/app.py", line 1821, in handle_user_exception
    reraise(exc_type, exc_value, tb)
  File "/Users/layne/WorkSpace/sdn-project/.venv/lib/python3.9/site-packages/flask/_compat.py", line 39, in reraise
    raise value
  File "/Users/layne/WorkSpace/sdn-project/.venv/lib/python3.9/site-packages/flask/app.py", line 1950, in full_dispatch_request
    rv = self.dispatch_request()
  File "/Users/layne/WorkSpace/sdn-project/.venv/lib/python3.9/site-packages/flask/app.py", line 1936, in dispatch_request
    return self.view_functions[rule.endpoint](**req.view_args)
  File "/Users/layne/WorkSpace/sdn-project/simulate/topology.py", line 27, in data
    req=requests.get(remote_ip+"/stats/portdesc/"+gol.dpid, timeout=(3,20))
AttributeError: module 'simulate.gol' has no attribute 'dpid'
[2024-09-13 00:24:01,685][app.py:1891][ERROR][4448510176] - Exception on /data-server [GET]
Traceback (most recent call last):
  File "/Users/layne/WorkSpace/sdn-project/.venv/lib/python3.9/site-packages/flask/app.py", line 2447, in wsgi_app
    response = self.full_dispatch_request()
  File "/Users/layne/WorkSpace/sdn-project/.venv/lib/python3.9/site-packages/flask/app.py", line 1952, in full_dispatch_request
    rv = self.handle_user_exception(e)
  File "/Users/layne/WorkSpace/sdn-project/.venv/lib/python3.9/site-packages/flask/app.py", line 1821, in handle_user_exception
    reraise(exc_type, exc_value, tb)
  File "/Users/layne/WorkSpace/sdn-project/.venv/lib/python3.9/site-packages/flask/_compat.py", line 39, in reraise
    raise value
  File "/Users/layne/WorkSpace/sdn-project/.venv/lib/python3.9/site-packages/flask/app.py", line 1950, in full_dispatch_request
    rv = self.dispatch_request()
  File "/Users/layne/WorkSpace/sdn-project/.venv/lib/python3.9/site-packages/flask/app.py", line 1936, in dispatch_request
    return self.view_functions[rule.endpoint](**req.view_args)
  File "/Users/layne/WorkSpace/sdn-project/simulate/topology.py", line 27, in data
    req=requests.get(remote_ip+"/stats/portdesc/"+gol.dpid, timeout=(3,20))
AttributeError: module 'simulate.gol' has no attribute 'dpid'
[2024-09-13 00:59:13,525][app.py:1891][ERROR][123145371705344] - Exception on /rule-list [GET]
Traceback (most recent call last):
  File "/Users/layne/WorkSpace/sdn-project/.venv/lib/python3.9/site-packages/flask/app.py", line 2447, in wsgi_app
    response = self.full_dispatch_request()
  File "/Users/layne/WorkSpace/sdn-project/.venv/lib/python3.9/site-packages/flask/app.py", line 1952, in full_dispatch_request
    rv = self.handle_user_exception(e)
  File "/Users/layne/WorkSpace/sdn-project/.venv/lib/python3.9/site-packages/flask/app.py", line 1821, in handle_user_exception
    reraise(exc_type, exc_value, tb)
  File "/Users/layne/WorkSpace/sdn-project/.venv/lib/python3.9/site-packages/flask/_compat.py", line 39, in reraise
    raise value
  File "/Users/layne/WorkSpace/sdn-project/.venv/lib/python3.9/site-packages/flask/app.py", line 1950, in full_dispatch_request
    rv = self.dispatch_request()
  File "/Users/layne/WorkSpace/sdn-project/.venv/lib/python3.9/site-packages/flask/app.py", line 1936, in dispatch_request
    return self.view_functions[rule.endpoint](**req.view_args)
  File "/Users/layne/WorkSpace/sdn-project/simulate/rule.py", line 76, in rule_list
    sqlHelper.add(sql,args)
  File "/Users/layne/WorkSpace/sdn-project/simulate/utils/sqlhelper.py", line 25, in add
    rowcount = cursor.execute(sql,args)
  File "/Users/layne/WorkSpace/sdn-project/.venv/lib/python3.9/site-packages/pymysql/cursors.py", line 163, in execute
    result = self._query(query)
  File "/Users/layne/WorkSpace/sdn-project/.venv/lib/python3.9/site-packages/pymysql/cursors.py", line 321, in _query
    conn.query(q)
  File "/Users/layne/WorkSpace/sdn-project/.venv/lib/python3.9/site-packages/pymysql/connections.py", line 505, in query
    self._affected_rows = self._read_query_result(unbuffered=unbuffered)
  File "/Users/layne/WorkSpace/sdn-project/.venv/lib/python3.9/site-packages/pymysql/connections.py", line 724, in _read_query_result
    result.read()
  File "/Users/layne/WorkSpace/sdn-project/.venv/lib/python3.9/site-packages/pymysql/connections.py", line 1069, in read
    first_packet = self.connection._read_packet()
  File "/Users/layne/WorkSpace/sdn-project/.venv/lib/python3.9/site-packages/pymysql/connections.py", line 676, in _read_packet
    packet.raise_for_error()
  File "/Users/layne/WorkSpace/sdn-project/.venv/lib/python3.9/site-packages/pymysql/protocol.py", line 223, in raise_for_error
    err.raise_mysql_exception(self._data)
  File "/Users/layne/WorkSpace/sdn-project/.venv/lib/python3.9/site-packages/pymysql/err.py", line 107, in raise_mysql_exception
    raise errorclass(errno, errval)
pymysql.err.ProgrammingError: (1146, "Table 'mydata.rules' doesn't exist")
